Workbook

Sheet Как работать
B1: Каталог разработчиков ИИ-решений — форма атрибутов
B2: Платформа Social1 · для сбора комментариев и первичного заполнения · версия от 22.09.2026
B4: ЗАЧЕМ
B5: Цель | C5: Согласовать состав атрибутов каталога и собрать данные о разработчиках до их внесения в портал. Атрибуты и справочники взяты из действующего кода каталога.
B6: ЛИСТЫ
B7: Атрибуты | C7: Все атрибуты, сгруппированные по смыслу (11 групп): что означает, тип, обязательность, кто заполняет, допустимые значения, пример и где используется. Комментарии — в зелёных колонках. Новые атрибуты — в группе 12 внизу.
B8: Разработчики | C8: Карточка разработчика: одна строка — один вендор, внутренняя команда или команда ДИТ.
B9: Портфолио | C9: Выполненные проекты разработчиков.
B10: Решения | C10: Готовые продукты, платформы, модели, услуги и технологии.
B11: Журнал | C11: Встречи, звонки, письма, запросы информации и демонстрации.
B12: Оценки | C12: Оценки по итогам совместной работы: качество, сроки, взаимодействие.
B13: Доступ | C13: Кому выдать роль в каталоге; представители компаний-поставщиков.
B14: Справочники | C14: Значения выпадающих списков. Предложения по их изменению — на листе «Атрибуты».
B15: ЦВЕТА
B16: Жёлтые ячейки | C16: Заполняются. Поля со звёздочкой * в заголовке обязательны.
B17: Зелёные ячейки | C17: Комментарии: замечание, предложение, автор, статус обсуждения.
B18: Серые ячейки | C18: Считаются сами или заполняются системой портала — не редактируйте.
B19: Строка 5 на листах | C19: Пример заполнения. Удалите или замените перед переносом данных в портал.
B20: КТО ЗАПОЛНЯЕТ
B21: Модератор каталога | C21: Базовые сведения: вид, название, реквизиты, контакты, статус, стоимость; журнал; оценки.
B22: Представитель разработчика | C22: Технологический профиль, портфолио и решения своей компании. Правки подтверждает модератор.
B23: Администратор каталога | C23: Роли доступа к каталогу.
B24: GOOGLE ТАБЛИЦЫ
B25: Перенос | C25: Загрузите файл на Google Диск и откройте как Google Таблицу (Файл → Открыть → Загрузка) или Файл → Импортировать → «Вставить новые листы». Выпадающие списки, проверки, формулы и цвета сохранятся. Для сбора комментариев откройте доступ «Комментатор» или «Редактор».
B26: Комментарии в ячейках | C26: Пояснения к колонкам — в примечаниях заголовков (наведите курсор). Обсуждать удобно и через комментарии Google Таблиц к конкретной ячейке.

Sheet Атрибуты
A1: Каталог разработчиков ИИ-решений — атрибуты для заполнения
A2: Все атрибуты карточки разработчика, портфолио, решений, журнала, оценок и доступа — сгруппированы по смыслу. Серые колонки описывают атрибут, зелёные — для ваших комментариев. Новые атрибуты предлагайте внизу листа.
A3: Описание атрибута | K3: Обсуждение — заполняют участники
A4: № | B4: Атрибут | C4: Описание | D4: Тип данных | E4: Обязательно | F4: Кто заполняет | G4: Допустимые значения, формат | H4: Пример | I4: Как используется в каталоге | J4: Лист формы | K4: Комментарий | L4: Предложение по изменению | M4: Автор комментария | N4: Статус обсуждения
A5: 1. Идентификация разработчика
A6: 1.1 | B6: Вид разработчика | C6: Внешний вендор, внутренняя команда или команда ДИТ. Определяет набор реквизитов. | D6: Список | E6: Да | F6: Модератор | G6: Внешний вендор / Внутренняя команда / Команда ДИТ | H6: Внешний вендор | I6: вкладки видов, сравнение | J6: Разработчики
A7: 1.2 | B7: Название | C7: Как разработчика называют в работе. | D7: Текст до 200 знаков | E7: Да | F7: Модератор | G7: Любой текст | H7: ООО «Нейросоциум» | I7: поиск, проверка дублей, сортировка | J7: Разработчики
A8: 1.3 | B8: Полное наименование юрлица | C8: Официальное наименование организации. | D8: Текст до 300 знаков | E8: Нет | F8: Модератор | G8: Только для внешнего вендора | H8: Общество с ограниченной ответственностью «Нейросоциум» | I8: поиск | J8: Разработчики
A9: 1.4 | B9: ИНН | C9: Идентификатор налогоплательщика. | D9: Текст из цифр | E9: Нет | F9: Модератор | G9: 10 цифр (организация) или 12 (ИП); уникален в каталоге; только для вендора | H9: 7700000011 | I9: проверка дублей, заполненность «Реквизиты» | J9: Разработчики
A10: 1.5 | B10: Подразделение | C10: Учреждение, управление или отдел, к которому относится команда. | D10: Текст до 300 знаков | E10: Нет | F10: Модератор | G10: Только для внутренней команды и команды ДИТ | H10: ТЦСО «Ярославский», отдел ИТ | I10: заполненность «Реквизиты» | J10: Разработчики
A11: 1.6 | B11: Город | C11: Где находится разработчик. | D11: Текст до 100 знаков | E11: Нет | F11: Модератор | G11: Любой текст | H11: Москва | I11: поиск | J11: Разработчики
A12: 1.7 | B12: Сайт | C12: Официальный сайт. | D12: Ссылка | E12: Нет | F12: Модератор | G12: http:// или https://; без схемы дополняется https:// | H12: https://neurosocium.example | I12: заполненность (для вендора) | J12: Разработчики
A13: 1.8 | B13: Год основания | C13: Год регистрации организации. | D13: Целое число | E13: Нет | F13: Модератор | G13: 1900 — текущий год; только для вендора | H13: 2016 | I13: карточка | J13: Разработчики
A14: 1.9 | B14: Размер команды, чел. | C14: Сколько человек в команде разработки. | D14: Целое число | E14: Нет | F14: Модератор или представитель | G14: 1 — 100 000 | H14: 60 | I14: сортировка, сравнение, заполненность | J14: Разработчики
A15: 2. Контакты и ответственность
A16: 2.1 | B16: Контактное лицо | C16: ФИО представителя разработчика для связи. | D16: Текст | E16: Нет | F16: Модератор | G16: Засчитывается вместе с почтой или телефоном | H16: Орлова Мария Сергеевна | I16: заполненность «Контактное лицо» | J16: Разработчики
A17: 2.2 | B17: Должность контакта | C17: Должность контактного лица. | D17: Текст | E17: Нет | F17: Модератор | G17: Любой текст | H17: Директор по работе с госсектором | I17: карточка | J17: Разработчики
A18: 2.3 | B18: Эл. почта контакта | C18: Адрес для связи. | D18: Эл. почта | E18: Нет | F18: Модератор | G18: Формат имя@домен | H18: m.orlova@neurosocium.example | I18: карточка, выгрузка | J18: Разработчики
A19: 2.4 | B19: Телефон контакта | C19: Телефон для связи. | D19: Текст | E19: Нет | F19: Модератор | G19: Любой формат | H19: +7 495 000-11-01 | I19: карточка, выгрузка | J19: Разработчики
A20: 2.5 | B20: Ведёт контакт | C20: Сотрудник ДТСЗН, отвечающий за отношения с разработчиком. | D20: Сотрудник платформы | E20: Нет | F20: Модератор | G20: Учётная запись платформы | H20: Ковалёв А. В. | I20: уведомления о правках представителя | J20: Разработчики
A21: 3. Статус отбора и условия
A22: 3.1 | B22: Статус | C22: Где разработчик на пути от первого упоминания до привлечения к работе. | D22: Список | E22: Да | F22: Модератор | G22: Новый / На проверке / Квалифицирован / Привлечён к работе / Не рекомендован / Архив | H22: Квалифицирован | I22: фильтр, сводка «Привлечены», архив скрыт | J22: Разработчики
A23: 3.2 | B23: Загрузка | C23: Насколько разработчик сейчас свободен. | D23: Список | E23: Нет | F23: Модератор или представитель | G23: Свободен / Загружен частично / Загружен полностью / Нет данных | H23: Загружен частично | I23: фильтр, сравнение | J23: Разработчики
A24: 3.3 | B24: Уровень стоимости | C24: Внутренний ориентир стоимости работ. | D24: Список | E24: Нет | F24: Модератор | G24: 1 — бюджетный / 2 — средний / 3 — высокий | H24: 2 — средний | I24: сравнение; представителю не показывается | J24: Разработчики
A25: 4. Технологический профиль
A26: 4.1 | B26: Описание | C26: Чем занимается, в чём силён, с какими заказчиками работал. | D26: Длинный текст | E26: Нет | F26: Модератор или представитель | G26: До 4000 знаков | H26: Виртуальные консультанты для органов соцзащиты… | I26: поиск, заполненность | J26: Разработчики
A27: 4.2 | B27: Компетенции в ИИ | C27: Какие задачи ИИ умеет решать разработчик. | D27: Несколько значений | E27: Нет | F27: Модератор или представитель | G27: Языковые модели и ассистенты; Поиск по документам (RAG); Обработка текстов; Распознавание и синтез речи; Компьютерное зрение; Распознавание документов; Прогнозная аналитика; Рекомендательные системы; Чат-боты и голосовые помощники; Роботизация процессов (RPA); Инженерия данных; MLOps и инфраструктура ИИ | H27: Языковые модели и ассистенты; Поиск по документам (RAG) | I27: фильтр (все выбранные сразу), сравнение, заполненность, сводка пробелов | J27: Разработчики
A28: 4.3 | B28: Отраслевой опыт | C28: В каких отраслях есть опыт проектов. | D28: Несколько значений | E28: Нет | F28: Модератор или представитель | G28: Социальная защита; Госуправление и госуслуги; Здравоохранение; Образование; Занятость и кадры; Финансы; Городское хозяйство | H28: Социальная защита | I28: фильтр | J28: Разработчики
A29: 4.4 | B29: Технологии и инструменты | C29: Свободный список технологий. | D29: Список меток | E29: Нет | F29: Модератор или представитель | G29: Через запятую, до 30 меток по 40 знаков | H29: Python, GigaChat, YandexGPT | I29: фильтр по метке, поиск | J29: Разработчики
A30: 5. Соответствие требованиям госсектора
A31: 5.1 | B31: ПО в реестре отечественного ПО | C31: Отмечается, если подтверждено документами или совместной работой. | D31: Да / Нет | E31: Нет | F31: Модератор или представитель | G31: Да / Нет | H31: Да | I31: фильтр, сравнение, заполненность | J31: Разработчики
A32: 5.2 | B32: Работа с персональными данными (152-ФЗ) | C32: Отмечается, если подтверждено документами или совместной работой. | D32: Да / Нет | E32: Нет | F32: Модератор или представитель | G32: Да / Нет | H32: Да | I32: фильтр, сравнение, заполненность | J32: Разработчики
A33: 5.3 | B33: Лицензии ФСТЭК, аттестованные решения | C33: Отмечается, если подтверждено документами или совместной работой. | D33: Да / Нет | E33: Нет | F33: Модератор или представитель | G33: Да / Нет | H33: Да | I33: фильтр, сравнение, заполненность | J33: Разработчики
A34: 5.4 | B34: Развёртывание в закрытом контуре | C34: Отмечается, если подтверждено документами или совместной работой. | D34: Да / Нет | E34: Нет | F34: Модератор или представитель | G34: Да / Нет | H34: Да | I34: фильтр, сравнение, заполненность | J34: Разработчики
A35: 5.5 | B35: Опыт госзаказа (44-ФЗ, 223-ФЗ) | C35: Отмечается, если подтверждено документами или совместной работой. | D35: Да / Нет | E35: Нет | F35: Модератор или представитель | G35: Да / Нет | H35: Да | I35: фильтр, сравнение, заполненность | J35: Разработчики
A36: 5.6 | B36: Субъект МСП | C36: Отмечается, если подтверждено документами или совместной работой. | D36: Да / Нет | E36: Нет | F36: Модератор или представитель | G36: Только для внешнего вендора | H36: Да | I36: фильтр, сравнение, заполненность | J36: Разработчики
A37: 6. Портфолио — выполненные проекты
A38: 6.1 | B38: Название проекта | C38: Что за проект. | D38: Текст до 300 знаков | E38: Да | F38: Модератор или представитель | G38: Любой текст | H38: Виртуальный консультант по мерам соцподдержки | I38: карточка | J38: Портфолио
A39: 6.2 | B39: Заказчик | C39: Для кого выполнен. | D39: Текст | E39: Нет | F39: Модератор или представитель | G39: Любой текст | H39: Региональный орган соцзащиты | I39: карточка | J39: Портфолио
A40: 6.3 | B40: Год | C40: Когда выполнен. | D40: Целое число | E40: Нет | F40: Модератор или представитель | G40: 1990 — следующий год | H40: 2024 | I40: сортировка портфолио | J40: Портфолио
...

Sheet Справочники
A1: Справочники каталога разработчиков ИИ-решений
A2: Значения выгружены из кода портала. Предложения по изменению справочников — на листе «Атрибуты», группа 12 внизу листа.
A4: Вид разработчика | B4: Статус | C4: Загрузка | D4: Уровень стоимости | E4: Компетенции в ИИ | F4: Отраслевой опыт | G4: Требования госсектора | H4: Тип решения | I4: Зрелость решения | J4: Лицензия | K4: Вид записи журнала | L4: Роль в каталоге | M4: Кто внёс | N4: Да / Нет | O4: Оценка | P4: Статус обсуждения
A5: Внешний вендор | B5: Новый | C5: Свободен | D5: 1 — бюджетный | E5: Языковые модели и ассистенты | F5: Социальная защита | G5: ПО в реестре отечественного ПО | H5: Готовый продукт | I5: Прототип | J5: Проприетарная | K5: Встреча | L5: Пользователь каталога | M5: Модератор | N5: Да | O5: 1 | P5: Открыт
A6: Внутренняя команда | B6: На проверке | C6: Загружен частично | D6: 2 — средний | E6: Поиск по документам (RAG) | F6: Госуправление и госуслуги | G6: Работа с персональными данными (152-ФЗ) | H6: Платформа | I6: Пилотное внедрение | J6: Открытый код | K6: Звонок | L6: Модератор каталога | M6: Представитель разработчика | N6: Нет | O6: 2 | P6: Принят
A7: Команда ДИТ | B7: Квалифицирован | C7: Загружен полностью | D7: 3 — высокий | E7: Обработка текстов | F7: Здравоохранение | G7: Лицензии ФСТЭК, аттестованные решения | H7: Модель или API | I7: Промышленная эксплуатация | J7: Облачный сервис (SaaS) | K7: Письмо | L7: Администратор каталога | O7: 3 | P7: Отклонён
B8: Привлечён к работе | C8: Нет данных | E8: Распознавание и синтез речи | F8: Образование | G8: Развёртывание в закрытом контуре | H8: Заказная разработка | K8: Запрос информации | L8: Представитель разработчика | O8: 4 | P8: Требует обсуждения
B9: Не рекомендован | E9: Компьютерное зрение | F9: Занятость и кадры | G9: Опыт госзаказа (44-ФЗ, 223-ФЗ) | H9: Технология, методика | K9: Демонстрация | O9: 5
B10: Архив | E10: Распознавание документов | F10: Финансы | G10: Субъект МСП | K10: Заметка
E11: Прогнозная аналитика | F11: Городское хозяйство
E12: Рекомендательные системы
E13: Чат-боты и голосовые помощники
E14: Роботизация процессов (RPA)
E15: Инженерия данных
E16: MLOps и инфраструктура ИИ

Sheet Разработчики
A1: Разработчики ИИ-решений — карточка
A2: Одна строка — один разработчик. Жёлтые ячейки заполняются, серые считаются сами, зелёные — для комментариев. * — обязательно. Наведите на заголовок колонки, чтобы увидеть пояснение. Строка 5 — пример.
A3: 1. Идентификация | J3: 2. Контакты и ответственность | O3: 3. Статус отбора и условия | R3: 4. Технологический профиль | T3: 5. Компетенции в ИИ — отметьте «Да» | AF3: 6. Отраслевой опыт — отметьте «Да» | AM3: 7. Соответствие требованиям госсектора — «Да», если подтверждено | AS3: 8. Расчёт (не заполнять) | AV3: 9. Обсуждение
A4: Вид разработчика * | B4: Название * | C4: Полное наименование юрлица | D4: ИНН | E4: Подразделение | F4: Город | G4: Сайт | H4: Год основания | I4: Размер команды, чел. | J4: Контактное лицо | K4: Должность контакта | L4: Эл. почта контакта | M4: Телефон контакта | N4: Ведёт контакт (сотрудник ДТСЗН) | O4: Статус * | P4: Загрузка | Q4: Уровень стоимости | R4: Описание | S4: Технологии и инструменты | T4: Языковые модели и ассистенты | U4: Поиск по документам (RAG) | V4: Обработка текстов | W4: Распознавание и синтез речи | X4: Компьютерное зрение | Y4: Распознавание документов | Z4: Прогнозная аналитика | AA4: Рекомендательные системы | AB4: Чат-боты и голосовые помощники | AC4: Роботизация процессов (RPA) | AD4: Инженерия данных | AE4: MLOps и инфраструктура ИИ | AF4: Социальная защита | AG4: Госуправление и госуслуги | AH4: Здравоохранение | AI4: Образование | AJ4: Занятость и кадры | AK4: Финансы | AL4: Городское хозяйство | AM4: ПО в реестре отечественного ПО | AN4: Работа с персональными данными (152-ФЗ) | AO4: Лицензии ФСТЭК, аттестованные решения | AP4: Развёртывание в закрытом контуре | AQ4: Опыт госзаказа (44-ФЗ, 223-ФЗ) | AR4: Субъект МСП | AS4: Проектов в портфолио | AT4: Решений | AU4: Заполненность | AV4: Комментарий | AW4: Автор комментария
A5: Внешний вендор | B5: ООО «Нейросоциум» (пример) | C5: Общество с ограниченной ответственностью «Нейросоциум» | D5: 7700000011 | F5: Москва | G5: https://neurosocium.example | H5: 2016 | I5: 60 | J5: Орлова Мария Сергеевна | K5: Директор по работе с госсектором | L5: m.orlova@neurosocium.example | M5: +7 495 000-11-01 | N5: Ковалёв А. В. | O5: Привлечён к работе | P5: Загружен частично | Q5: 2 — средний | R5: Виртуальные консультанты и поиск по нормативной базе для органов соцзащиты. | S5: Python, GigaChat, YandexGPT | T5: Да | U5: Да | V5: Да | AB5: Да | AF5: Да | AG5: Да | AM5: Да | AN5: Да | AP5: Да | AQ5: Да | AR5: Да | AS5: =IF($B5="","",COUNTIF('Портфолио'!$A$5:$A$205,$B5)) | AT5: =IF($B5="","",COUNTIF('Решения'!$A$5:$A$205,$B5)) | AU5: =IF($B5="","",(15*(R5<>"")+15*(COUNTIF(T5:AE5,"Да")>0)+15*AND(J5<>"",OR(L5<>"",M5<>""))+15*(AS5>0)+10*(AT5>0)+10*(COUNTIF(AM5:AR5,"Да")>0)+10*IF(A5="Внешний вендор",D5<>"",E5<>"")+5*(I5<>"")+5*IF(A5="Внешний вендор",G5<>"",TRUE))/100) | AV5: Пример строки — удалите или замените своими данными | AW5: Составитель формы
AS6: =IF($B6="","",COUNTIF('Портфолио'!$A$5:$A$205,$B6)) | AT6: =IF($B6="","",COUNTIF('Решения'!$A$5:$A$205,$B6)) | AU6: =IF($B6="","",(15*(R6<>"")+15*(COUNTIF(T6:AE6,"Да")>0)+15*AND(J6<>"",OR(L6<>"",M6<>""))+15*(AS6>0)+10*(AT6>0)+10*(COUNTIF(AM6:AR6,"Да")>0)+10*IF(A6="Внешний вендор",D6<>"",E6<>"")+5*(I6<>"")+5*IF(A6="Внешний вендор",G6<>"",TRUE))/100)
AS7: =IF($B7="","",COUNTIF('Портфолио'!$A$5:$A$205,$B7)) | AT7: =IF($B7="","",COUNTIF('Решения'!$A$5:$A$205,$B7)) | AU7: =IF($B7="","",(15*(R7<>"")+15*(COUNTIF(T7:AE7,"Да")>0)+15*AND(J7<>"",OR(L7<>"",M7<>""))+15*(AS7>0)+10*(AT7>0)+10*(COUNTIF(AM7:AR7,"Да")>0)+10*IF(A7="Внешний вендор",D7<>"",E7<>"")+5*(I7<>"")+5*IF(A7="Внешний вендор",G7<>"",TRUE))/100)
AS8: =IF($B8="","",COUNTIF('Портфолио'!$A$5:$A$205,$B8)) | AT8: =IF($B8="","",COUNTIF('Решения'!$A$5:$A$205,$B8)) | AU8: =IF($B8="","",(15*(R8<>"")+15*(COUNTIF(T8:AE8,"Да")>0)+15*AND(J8<>"",OR(L8<>"",M8<>""))+15*(AS8>0)+10*(AT8>0)+10*(COUNTIF(AM8:AR8,"Да")>0)+10*IF(A8="Внешний вендор",D8<>"",E8<>"")+5*(I8<>"")+5*IF(A8="Внешний вендор",G8<>"",TRUE))/100)
AS9: =IF($B9="","",COUNTIF('Портфолио'!$A$5:$A$205,$B9)) | AT9: =IF($B9="","",COUNTIF('Решения'!$A$5:$A$205,$B9)) | AU9: =IF($B9="","",(15*(R9<>"")+15*(COUNTIF(T9:AE9,"Да")>0)+15*AND(J9<>"",OR(L9<>"",M9<>""))+15*(AS9>0)+10*(AT9>0)+10*(COUNTIF(AM9:AR9,"Да")>0)+10*IF(A9="Внешний вендор",D9<>"",E9<>"")+5*(I9<>"")+5*IF(A9="Внешний вендор",G9<>"",TRUE))/100)
AS10: =IF($B10="","",COUNTIF('Портфолио'!$A$5:$A$205,$B10)) | AT10: =IF($B10="","",COUNTIF('Решения'!$A$5:$A$205,$B10)) | AU10: =IF($B10="","",(15*(R10<>"")+15*(COUNTIF(T10:AE10,"Да")>0)+15*AND(J10<>"",OR(L10<>"",M10<>""))+15*(AS10>0)+10*(AT10>0)+10*(COUNTIF(AM10:AR10,"Да")>0)+10*IF(A10="Внешний вендор",D10<>"",E10<>"")+5*(I10<>"")+5*IF(A10="Внешний вендор",G10<>"",TRUE))/100)
AS11: =IF($B11="","",COUNTIF('Портфолио'!$A$5:$A$205,$B11)) | AT11: =IF($B11="","",COUNTIF('Решения'!$A$5:$A$205,$B11)) | AU11: =IF($B11="","",(15*(R11<>"")+15*(COUNTIF(T11:AE11,"Да")>0)+15*AND(J11<>"",OR(L11<>"",M11<>""))+15*(AS11>0)+10*(AT11>0)+10*(COUNTIF(AM11:AR11,"Да")>0)+10*IF(A11="Внешний вендор",D11<>"",E11<>"")+5*(I11<>"")+5*IF(A11="Внешний вендор",G11<>"",TRUE))/100)
AS12: =IF($B12="","",COUNTIF('Портфолио'!$A$5:$A$205,$B12)) | AT12: =IF($B12="","",COUNTIF('Решения'!$A$5:$A$205,$B12)) | AU12: =IF($B12="","",(15*(R12<>"")+15*(COUNTIF(T12:AE12,"Да")>0)+15*AND(J12<>"",OR(L12<>"",M12<>""))+15*(AS12>0)+10*(AT12>0)+10*(COUNTIF(AM12:AR12,"Да")>0)+10*IF(A12="Внешний вендор",D12<>"",E12<>"")+5*(I12<>"")+5*IF(A12="Внешний вендор",G12<>"",TRUE))/100)
AS13: =IF($B13="","",COUNTIF('Портфолио'!$A$5:$A$205,$B13)) | AT13: =IF($B13="","",COUNTIF('Решения'!$A$5:$A$205,$B13)) | AU13: =IF($B13="","",(15*(R13<>"")+15*(COUNTIF(T13:AE13,"Да")>0)+15*AND(J13<>"",OR(L13<>"",M13<>""))+15*(AS13>0)+10*(AT13>0)+10*(COUNTIF(AM13:AR13,"Да")>0)+10*IF(A13="Внешний вендор",D13<>"",E13<>"")+5*(I13<>"")+5*IF(A13="Внешний вендор",G13<>"",TRUE))/100)
AS14: =IF($B14="","",COUNTIF('Портфолио'!$A$5:$A$205,$B14)) | AT14: =IF($B14="","",COUNTIF('Решения'!$A$5:$A$205,$B14)) | AU14: =IF($B14="","",(15*(R14<>"")+15*(COUNTIF(T14:AE14,"Да")>0)+15*AND(J14<>"",OR(L14<>"",M14<>""))+15*(AS14>0)+10*(AT14>0)+10*(COUNTIF(AM14:AR14,"Да")>0)+10*IF(A14="Внешний вендор",D14<>"",E14<>"")+5*(I14<>"")+5*IF(A14="Внешний вендор",G14<>"",TRUE))/100)
AS15: =IF($B15="","",COUNTIF('Портфолио'!$A$5:$A$205,$B15)) | AT15: =IF($B15="","",COUNTIF('Решения'!$A$5:$A$205,$B15)) | AU15: =IF($B15="","",(15*(R15<>"")+15*(COUNTIF(T15:AE15,"Да")>0)+15*AND(J15<>"",OR(L15<>"",M15<>""))+15*(AS15>0)+10*(AT15>0)+10*(COUNTIF(AM15:AR15,"Да")>0)+10*IF(A15="Внешний вендор",D15<>"",E15<>"")+5*(I15<>"")+5*IF(A15="Внешний вендор",G15<>"",TRUE))/100)
AS16: =IF($B16="","",COUNTIF('Портфолио'!$A$5:$A$205,$B16)) | AT16: =IF($B16="","",COUNTIF('Решения'!$A$5:$A$205,$B16)) | AU16: =IF($B16="","",(15*(R16<>"")+15*(COUNTIF(T16:AE16,"Да")>0)+15*AND(J16<>"",OR(L16<>"",M16<>""))+15*(AS16>0)+10*(AT16>0)+10*(COUNTIF(AM16:AR16,"Да")>0)+10*IF(A16="Внешний вендор",D16<>"",E16<>"")+5*(I16<>"")+5*IF(A16="Внешний вендор",G16<>"",TRUE))/100)
AS17: =IF($B17="","",COUNTIF('Портфолио'!$A$5:$A$205,$B17)) | AT17: =IF($B17="","",COUNTIF('Решения'!$A$5:$A$205,$B17)) | AU17: =IF($B17="","",(15*(R17<>"")+15*(COUNTIF(T17:AE17,"Да")>0)+15*AND(J17<>"",OR(L17<>"",M17<>""))+15*(AS17>0)+10*(AT17>0)+10*(COUNTIF(AM17:AR17,"Да")>0)+10*IF(A17="Внешний вендор",D17<>"",E17<>"")+5*(I17<>"")+5*IF(A17="Внешний вендор",G17<>"",TRUE))/100)
... AS205: =IF($B205="","",COUNTIF('Портфолио'!$A$5:$A$205,$B205)) | AT205: =IF($B205="","",COUNTIF('Решения'!$A$5:$A$205,$B205)) | AU205: =IF($B205="","",(15*(R205<>"")+15*(COUNTIF(T205:AE205,"Да")>0)+15*AND(J205<>"",OR(L205<>"",M205<>""))+15*(AS205>0)+10*(AT205>0)+10*(COUNTIF(AM205:AR205,"Да")>0)+10*IF(A205="Внешний вендор",D205<>"",E205<>"")+5*(I205<>"")+5*IF(A205="Внешний вендор",G205<>"",TRUE))/100)

Sheet Портфолио
A1: Портфолио — выполненные проекты
A2: Одна строка — один проект. Заполняет модератор или представитель разработчика. Строка 5 — пример.
A3: Разработчик | B3: Проект | K3: Обсуждение
A4: Разработчик * | B4: Название проекта * | C4: Заказчик | D4: Год | E4: Заказчик из госсектора | F4: Что сделано | G4: Результат (измеримый эффект) | H4: Технологии | I4: Ссылка на описание | J4: Кто внёс | K4: Комментарий | L4: Автор комментария
A5: ООО «Нейросоциум» (пример) | B5: Виртуальный консультант по мерам социальной поддержки | C5: Региональный орган соцзащиты | D5: 2024 | E5: Да | F5: Ассистент отвечает на вопросы о пособиях и ведёт к подаче заявления. | G5: 62% обращений без оператора, ответ — с 2 дней до минуты | H5: GigaChat, RAG | J5: Модератор

Sheet Решения
A1: Решения и технологии разработчиков
A2: Одна строка — одно решение. Решения видны пользователям каталога во вкладке «Решения и технологии». Строка 5 — пример.
A3: Разработчик | B3: Решение | L3: Какие задачи закрывает — отметьте «Да» | X3: Обсуждение
A4: Разработчик * | B4: Название решения * | C4: Тип * | D4: Зрелость * | E4: Лицензия | F4: В реестре отечественного ПО | G4: Описание: какую задачу решает | H4: Технологии | I4: Стоимость, условия | J4: Ссылка | K4: Кто внёс | L4: Языковые модели и ассистенты | M4: Поиск по документам (RAG) | N4: Обработка текстов | O4: Распознавание и синтез речи | P4: Компьютерное зрение | Q4: Распознавание документов | R4: Прогнозная аналитика | S4: Рекомендательные системы | T4: Чат-боты и голосовые помощники | U4: Роботизация процессов (RPA) | V4: Инженерия данных | W4: MLOps и инфраструктура ИИ | X4: Комментарий | Y4: Автор комментария
A5: ООО «Нейросоциум» (пример) | B5: Социум.Ассистент | C5: Платформа | D5: Промышленная эксплуатация | E5: Проприетарная | F5: Да | G5: Платформа диалоговых ассистентов для граждан и сотрудников. | H5: GigaChat, YandexGPT | I5: Лицензия на инсталляцию плюс сопровождение | K5: Представитель разработчика | L5: Да | M5: Да | T5: Да

Sheet Журнал
A1: Журнал взаимодействий
A2: Одна строка — одна встреча, звонок, письмо, запрос или демонстрация. Ведёт модератор каталога. Строка 5 — пример.
A3: Разработчик | B3: Запись | F3: Обсуждение
A4: Разработчик * | B4: Дата * | C4: Вид записи * | D4: Содержание: о чём договорились * | E4: Автор записи | F4: Комментарий | G4: Автор комментария
A5: ООО «Нейросоциум» (пример) | B5: 46280 | C5: Демонстрация | D5: Показали консультанта на реальных вопросах о пособиях. Договорились о пилоте. | E5: Ковалёв А. В.

Sheet Оценки
A1: Оценки по итогам совместной работы
A2: Одна оценка от человека на разработчика; повторная заменяет прежнюю. Оценивает модератор каталога по пятибалльной шкале. Строка 5 — пример.
A3: Разработчик | B3: Оценка | I3: Обсуждение
A4: Разработчик * | B4: Оценивающий * | C4: Проект | D4: Качество результата * | E4: Соблюдение сроков * | F4: Взаимодействие * | G4: Средняя | H4: Комментарий к оценке | I4: Комментарий | J4: Автор комментария
A5: ООО «Нейросоциум» (пример) | B5: Ковалёв А. В. | C5: Пилот консультанта в ТЦСО «Ярославский» | D5: 5 | E5: 4 | F5: 5 | G5: =IF(COUNT(D5:F5)=3,AVERAGE(D5:F5),"") | H5: Сильная команда, сдвинули срок на неделю из-за интеграции.
G6: =IF(COUNT(D6:F6)=3,AVERAGE(D6:F6),"")
G7: =IF(COUNT(D7:F7)=3,AVERAGE(D7:F7),"")
G8: =IF(COUNT(D8:F8)=3,AVERAGE(D8:F8),"")
G9: =IF(COUNT(D9:F9)=3,AVERAGE(D9:F9),"")
G10: =IF(COUNT(D10:F10)=3,AVERAGE(D10:F10),"")
G11: =IF(COUNT(D11:F11)=3,AVERAGE(D11:F11),"")
G12: =IF(COUNT(D12:F12)=3,AVERAGE(D12:F12),"")
G13: =IF(COUNT(D13:F13)=3,AVERAGE(D13:F13),"")
G14: =IF(COUNT(D14:F14)=3,AVERAGE(D14:F14),"")
G15: =IF(COUNT(D15:F15)=3,AVERAGE(D15:F15),"")
G16: =IF(COUNT(D16:F16)=3,AVERAGE(D16:F16),"")
G17: =IF(COUNT(D17:F17)=3,AVERAGE(D17:F17),"")
... G205: =IF(COUNT(D205:F205)=3,AVERAGE(D205:F205),"")

Sheet Доступ
A1: Доступ к каталогу и представители разработчиков
A2: Кому выдать роль в каталоге. Представитель разработчика — сотрудник компании-поставщика, привязывается к карточке своей компании. Строка 5 — пример.
A3: Сотрудник | D3: Доступ | G3: Обсуждение
A4: ФИО * | B4: Эл. почта (учётная запись на платформе) * | C4: Подразделение или компания | D4: Роль в каталоге * | E4: Разработчик (для представителя) | F4: Основание, кто запросил | G4: Комментарий | H4: Автор комментария
A5: Абрамов Виктор Тимурович | B5: vendor@cst.ru | C5: ЦСТ | D5: Представитель разработчика | E5: АО «Зоркий Код» | F5: Письмо компании от 10.09.2026
